Workbook

Sheet Marketing Campaigns 22.11.22
A1: Keys & Granularity | G1: fb/insta channel | H1: googleads channel | I1: pinterest/tiktok channel | J1: Klaviyo
A2: First Day of the Week | B2: Week | C2: Month | D2: Quarter | E2: product_category | F2: All | G2: fb/insta_total_Budget | H2: googleads_total_Budget | I2: rest_total_budget | J2: klaviyo_numberofcampaigns | K2: klaviyo_grossreach_perweek
A3: 44197 | B3: 53 | C3: 1 | D3: 1 | E3: None | F3: 0 | G3: =INDEX(weekly!$E$2:$E$188,MATCH('Marketing Campaigns 22.11.22'!L3,weekly!$H$2:$H$188,0)) -> 0 | H3: =INDEX(weekly!$D$2:$D$188,MATCH('Marketing Campaigns 22.11.22'!L3,weekly!$H$2:$H$188,0)) -> 0 | I3: =INDEX(weekly!$F$2:$F$188,MATCH('Marketing Campaigns 22.11.22'!L3,weekly!$H$2:$H$188,0)) -> 0 | J3: 0 | K3: 0 | L3: =B3&"-"&C3&"-"&M3 -> 53-1-2021 | M3: =YEAR(A3) -> 2021
A4: 44197 | B4: 53 | C4: 1 | D4: 1 | E4: Premium Truthahnhappen | F4: 0 | G4: =INDEX(weekly!$E$2:$E$188,MATCH('Marketing Campaigns 22.11.22'!L4,weekly!$H$2:$H$188,0)) -> 0 | H4: =INDEX(weekly!$D$2:$D$188,MATCH('Marketing Campaigns 22.11.22'!L4,weekly!$H$2:$H$188,0)) -> 0 | I4: =INDEX(weekly!$F$2:$F$188,MATCH('Marketing Campaigns 22.11.22'!L4,weekly!$H$2:$H$188,0)) -> 0 | J4: 0 | K4: 0 | L4: =B4&"-"&C4&"-"&M4 -> 53-1-2021 | M4: =YEAR(A4) -> 2021
A5: 44197 | B5: 53 | C5: 1 | D5: 1 | E5: Probierpaket | F5: 0 | G5: =INDEX(weekly!$E$2:$E$188,MATCH('Marketing Campaigns 22.11.22'!L5,weekly!$H$2:$H$188,0)) -> 0 | H5: =INDEX(weekly!$D$2:$D$188,MATCH('Marketing Campaigns 22.11.22'!L5,weekly!$H$2:$H$188,0)) -> 0 | I5: =INDEX(weekly!$F$2:$F$188,MATCH('Marketing Campaigns 22.11.22'!L5,weekly!$H$2:$H$188,0)) -> 0 | J5: 0 | K5: 0 | L5: =B5&"-"&C5&"-"&M5 -> 53-1-2021 | M5: =YEAR(A5) -> 2021
A6: 44197 | B6: 53 | C6: 1 | D6: 1 | E6: Premium Trockenfutter mit<br> Lachs und Süßkartoffel für sensible Katzenmägen <br> (1,5kg / 6kg) | F6: 0 | G6: =INDEX(weekly!$E$2:$E$188,MATCH('Marketing Campaigns 22.11.22'!L6,weekly!$H$2:$H$188,0)) -> 0 | H6: =INDEX(weekly!$D$2:$D$188,MATCH('Marketing Campaigns 22.11.22'!L6,weekly!$H$2:$H$188,0)) -> 0 | I6: =INDEX(weekly!$F$2:$F$188,MATCH('Marketing Campaigns 22.11.22'!L6,weekly!$H$2:$H$188,0)) -> 0 | J6: 0 | K6: 0 | L6: =B6&"-"&C6&"-"&M6 -> 53-1-2021 | M6: =YEAR(A6) -> 2021
A7: 44197 | B7: 53 | C7: 1 | D7: 1 | E7: Premium Trockenfutter mit <br> Lachs & Hering <br> (2kg / 12kg) | F7: 0 | G7: =INDEX(weekly!$E$2:$E$188,MATCH('Marketing Campaigns 22.11.22'!L7,weekly!$H$2:$H$188,0)) -> 0 | H7: =INDEX(weekly!$D$2:$D$188,MATCH('Marketing Campaigns 22.11.22'!L7,weekly!$H$2:$H$188,0)) -> 0 | I7: =INDEX(weekly!$F$2:$F$188,MATCH('Marketing Campaigns 22.11.22'!L7,weekly!$H$2:$H$188,0)) -> 0 | J7: 0 | K7: 0 | L7: =B7&"-"&C7&"-"&M7 -> 53-1-2021 | M7: =YEAR(A7) -> 2021
A8: 44197 | B8: 53 | C8: 1 | D8: 1 | E8: Funktionssnack | F8: 0 | G8: =INDEX(weekly!$E$2:$E$188,MATCH('Marketing Campaigns 22.11.22'!L8,weekly!$H$2:$H$188,0)) -> 0 | H8: =INDEX(weekly!$D$2:$D$188,MATCH('Marketing Campaigns 22.11.22'!L8,weekly!$H$2:$H$188,0)) -> 0 | I8: =INDEX(weekly!$F$2:$F$188,MATCH('Marketing Campaigns 22.11.22'!L8,weekly!$H$2:$H$188,0)) -> 0 | J8: 0 | K8: 0 | L8: =B8&"-"&C8&"-"&M8 -> 53-1-2021 | M8: =YEAR(A8) -> 2021
A9: 44197 | B9: 53 | C9: 1 | D9: 1 | E9: Snack | F9: 0 | G9: =INDEX(weekly!$E$2:$E$188,MATCH('Marketing Campaigns 22.11.22'!L9,weekly!$H$2:$H$188,0)) -> 0 | H9: =INDEX(weekly!$D$2:$D$188,MATCH('Marketing Campaigns 22.11.22'!L9,weekly!$H$2:$H$188,0)) -> 0 | I9: =INDEX(weekly!$F$2:$F$188,MATCH('Marketing Campaigns 22.11.22'!L9,weekly!$H$2:$H$188,0)) -> 0 | J9: 0 | K9: 0 | L9: =B9&"-"&C9&"-"&M9 -> 53-1-2021 | M9: =YEAR(A9) -> 2021
A10: 44197 | B10: 53 | C10: 1 | D10: 1 | E10: Backmischung | F10: 0 | G10: =INDEX(weekly!$E$2:$E$188,MATCH('Marketing Campaigns 22.11.22'!L10,weekly!$H$2:$H$188,0)) -> 0 | H10: =INDEX(weekly!$D$2:$D$188,MATCH('Marketing Campaigns 22.11.22'!L10,weekly!$H$2:$H$188,0)) -> 0 | I10: =INDEX(weekly!$F$2:$F$188,MATCH('Marketing Campaigns 22.11.22'!L10,weekly!$H$2:$H$188,0)) -> 0 | J10: 0 | K10: 0 | L10: =B10&"-"&C10&"-"&M10 -> 53-1-2021 | M10: =YEAR(A10) -> 2021
A11: 44197 | B11: 53 | C11: 1 | D11: 1 | E11: Nassfutter | F11: 0 | G11: =INDEX(weekly!$E$2:$E$188,MATCH('Marketing Campaigns 22.11.22'!L11,weekly!$H$2:$H$188,0)) -> 0 | H11: =INDEX(weekly!$D$2:$D$188,MATCH('Marketing Campaigns 22.11.22'!L11,weekly!$H$2:$H$188,0)) -> 0 | I11: =INDEX(weekly!$F$2:$F$188,MATCH('Marketing Campaigns 22.11.22'!L11,weekly!$H$2:$H$188,0)) -> 0 | J11: 0 | K11: 0 | L11: =B11&"-"&C11&"-"&M11 -> 53-1-2021 | M11: =YEAR(A11) -> 2021
A12: 44197 | B12: 53 | C12: 1 | D12: 1 | E12: Mixpaket | F12: 0 | G12: =INDEX(weekly!$E$2:$E$188,MATCH('Marketing Campaigns 22.11.22'!L12,weekly!$H$2:$H$188,0)) -> 0 | H12: =INDEX(weekly!$D$2:$D$188,MATCH('Marketing Campaigns 22.11.22'!L12,weekly!$H$2:$H$188,0)) -> 0 | I12: =INDEX(weekly!$F$2:$F$188,MATCH('Marketing Campaigns 22.11.22'!L12,weekly!$H$2:$H$188,0)) -> 0 | J12: 0 | K12: 0 | L12: =B12&"-"&C12&"-"&M12 -> 53-1-2021 | M12: =YEAR(A12) -> 2021
A13: 44197 | B13: 53 | C13: 1 | D13: 1 | E13: Premium Trockenfutter mit <br> Lamm, Süßkartoffel und Leinsamen <br> (400g / 2kg / 8kg / 12kg) | F13: 0 | G13: =INDEX(weekly!$E$2:$E$188,MATCH('Marketing Campaigns 22.11.22'!L13,weekly!$H$2:$H$188,0)) -> 0 | H13: =INDEX(weekly!$D$2:$D$188,MATCH('Marketing Campaigns 22.11.22'!L13,weekly!$H$2:$H$188,0)) -> 0 | I13: =INDEX(weekly!$F$2:$F$188,MATCH('Marketing Campaigns 22.11.22'!L13,weekly!$H$2:$H$188,0)) -> 0 | J13: 0 | K13: 0 | L13: =B13&"-"&C13&"-"&M13 -> 53-1-2021 | M13: =YEAR(A13) -> 2021
A14: 44197 | B14: 53 | C14: 1 | D14: 1 | E14: Trockenfutter | F14: 0 | G14: =INDEX(weekly!$E$2:$E$188,MATCH('Marketing Campaigns 22.11.22'!L14,weekly!$H$2:$H$188,0)) -> 0 | H14: =INDEX(weekly!$D$2:$D$188,MATCH('Marketing Campaigns 22.11.22'!L14,weekly!$H$2:$H$188,0)) -> 0 | I14: =INDEX(weekly!$F$2:$F$188,MATCH('Marketing Campaigns 22.11.22'!L14,weekly!$H$2:$H$188,0)) -> 0 | J14: 0 | K14: 0 | L14: =B14&"-"&C14&"-"&M14 -> 53-1-2021 | M14: =YEAR(A14) -> 2021
... A1967: 45103 | B1967: 26 | C1967: 6 | D1967: 2 | E1967: DUMMY2 | F1967: 0 | G1967: =INDEX(weekly!$E$2:$E$188,MATCH('Marketing Campaigns 22.11.22'!L1967,weekly!$H$2:$H$188,0)) -> 3859.7406 | H1967: =INDEX(weekly!$D$2:$D$188,MATCH('Marketing Campaigns 22.11.22'!L1967,weekly!$H$2:$H$188,0)) -> 11845.561 | I1967: =INDEX(weekly!$F$2:$F$188,MATCH('Marketing Campaigns 22.11.22'!L1967,weekly!$H$2:$H$188,0)) -> 5493.3061 | J1967: 0 | K1967: 0 | L1967: =B1967&"-"&C1967&"-"&M1967 -> 26-6-2023 | M1967: =YEAR(A1967) -> 2023
A1968: =DATE(2023, 1, -2) - WEEKDAY(DATE(2023, 1, 3)) + B1968 * 7 -> 45110 | B1968: 27 | C1968: =MONTH(A1968) -> 7 | D1968: =CEILING(C1968 / 3,1) -> 3 | E1968: None | F1968: 0 | G1968: =INDEX(weekly!$E$2:$E$188,MATCH('Marketing Campaigns 22.11.22'!L1968,weekly!$H$2:$H$188,0)) -> 5937.136 | H1968: =INDEX(weekly!$D$2:$D$188,MATCH('Marketing Campaigns 22.11.22'!L1968,weekly!$H$2:$H$188,0)) -> 17309.704 | I1968: =INDEX(weekly!$F$2:$F$188,MATCH('Marketing Campaigns 22.11.22'!L1968,weekly!$H$2:$H$188,0)) -> 6353.2139 | J1968: 0 | K1968: 0 | L1968: =B1968&"-"&C1968&"-"&M1968 -> 27-7-2023 | M1968: =YEAR(A1968) -> 2023
A1969: =DATE(2023, 1, -2) - WEEKDAY(DATE(2023, 1, 3)) + B1969 * 7 -> 45110 | B1969: 27 | C1969: =MONTH(A1969) -> 7 | D1969: =CEILING(C1969 / 3,1) -> 3 | E1969: Premium Truthahnhappen | F1969: 0 | G1969: =INDEX(weekly!$E$2:$E$188,MATCH('Marketing Campaigns 22.11.22'!L1969,weekly!$H$2:$H$188,0)) -> 5937.136 | H1969: =INDEX(weekly!$D$2:$D$188,MATCH('Marketing Campaigns 22.11.22'!L1969,weekly!$H$2:$H$188,0)) -> 17309.704 | I1969: =INDEX(weekly!$F$2:$F$188,MATCH('Marketing Campaigns 22.11.22'!L1969,weekly!$H$2:$H$188,0)) -> 6353.2139 | J1969: 0 | K1969: 0 | L1969: =B1969&"-"&C1969&"-"&M1969 -> 27-7-2023 | M1969: =YEAR(A1969) -> 2023
A1970: =DATE(2023, 1, -2) - WEEKDAY(DATE(2023, 1, 3)) + B1970 * 7 -> 45110 | B1970: 27 | C1970: =MONTH(A1970) -> 7 | D1970: =CEILING(C1970 / 3,1) -> 3 | E1970: Probierpaket | F1970: 0 | G1970: =INDEX(weekly!$E$2:$E$188,MATCH('Marketing Campaigns 22.11.22'!L1970,weekly!$H$2:$H$188,0)) -> 5937.136 | H1970: =INDEX(weekly!$D$2:$D$188,MATCH('Marketing Campaigns 22.11.22'!L1970,weekly!$H$2:$H$188,0)) -> 17309.704 | I1970: =INDEX(weekly!$F$2:$F$188,MATCH('Marketing Campaigns 22.11.22'!L1970,weekly!$H$2:$H$188,0)) -> 6353.2139 | J1970: 0 | K1970: 0 | L1970: =B1970&"-"&C1970&"-"&M1970 -> 27-7-2023 | M1970: =YEAR(A1970) -> 2023
A1971: =DATE(2023, 1, -2) - WEEKDAY(DATE(2023, 1, 3)) + B1971 * 7 -> 45110 | B1971: 27 | C1971: =MONTH(A1971) -> 7 | D1971: =CEILING(C1971 / 3,1) -> 3 | E1971: Premium Trockenfutter mit<br> Lachs und Süßkartoffel für sensible Katzenmägen <br> (1,5kg / 6kg) | F1971: 0 | G1971: =INDEX(weekly!$E$2:$E$188,MATCH('Marketing Campaigns 22.11.22'!L1971,weekly!$H$2:$H$188,0)) -> 5937.136 | H1971: =INDEX(weekly!$D$2:$D$188,MATCH('Marketing Campaigns 22.11.22'!L1971,weekly!$H$2:$H$188,0)) -> 17309.704 | I1971: =INDEX(weekly!$F$2:$F$188,MATCH('Marketing Campaigns 22.11.22'!L1971,weekly!$H$2:$H$188,0)) -> 6353.2139 | J1971: 0 | K1971: 0 | L1971: =B1971&"-"&C1971&"-"&M1971 -> 27-7-2023 | M1971: =YEAR(A1971) -> 2023
A1972: =DATE(2023, 1, -2) - WEEKDAY(DATE(2023, 1, 3)) + B1972 * 7 -> 45110 | B1972: 27 | C1972: =MONTH(A1972) -> 7 | D1972: =CEILING(C1972 / 3,1) -> 3 | E1972: Premium Trockenfutter mit <br> Lachs & Hering <br> (2kg / 12kg) | F1972: 0 | G1972: =INDEX(weekly!$E$2:$E$188,MATCH('Marketing Campaigns 22.11.22'!L1972,weekly!$H$2:$H$188,0)) -> 5937.136 | H1972: =INDEX(weekly!$D$2:$D$188,MATCH('Marketing Campaigns 22.11.22'!L1972,weekly!$H$2:$H$188,0)) -> 17309.704 | I1972: =INDEX(weekly!$F$2:$F$188,MATCH('Marketing Campaigns 22.11.22'!L1972,weekly!$H$2:$H$188,0)) -> 6353.2139 | J1972: 0 | K1972: 0 | L1972: =B1972&"-"&C1972&"-"&M1972 -> 27-7-2023 | M1972: =YEAR(A1972) -> 2023
A1973: =DATE(2023, 1, -2) - WEEKDAY(DATE(2023, 1, 3)) + B1973 * 7 -> 45110 | B1973: 27 | C1973: =MONTH(A1973) -> 7 | D1973: =CEILING(C1973 / 3,1) -> 3 | E1973: Funktionssnack | F1973: 0 | G1973: =INDEX(weekly!$E$2:$E$188,MATCH('Marketing Campaigns 22.11.22'!L1973,weekly!$H$2:$H$188,0)) -> 5937.136 | H1973: =INDEX(weekly!$D$2:$D$188,MATCH('Marketing Campaigns 22.11.22'!L1973,weekly!$H$2:$H$188,0)) -> 17309.704 | I1973: =INDEX(weekly!$F$2:$F$188,MATCH('Marketing Campaigns 22.11.22'!L1973,weekly!$H$2:$H$188,0)) -> 6353.2139 | J1973: 0 | K1973: 0 | L1973: =B1973&"-"&C1973&"-"&M1973 -> 27-7-2023 | M1973: =YEAR(A1973) -> 2023
A1974: =DATE(2023, 1, -2) - WEEKDAY(DATE(2023, 1, 3)) + B1974 * 7 -> 45110 | B1974: 27 | C1974: =MONTH(A1974) -> 7 | D1974: =CEILING(C1974 / 3,1) -> 3 | E1974: Snack | F1974: 0 | G1974: =INDEX(weekly!$E$2:$E$188,MATCH('Marketing Campaigns 22.11.22'!L1974,weekly!$H$2:$H$188,0)) -> 5937.136 | H1974: =INDEX(weekly!$D$2:$D$188,MATCH('Marketing Campaigns 22.11.22'!L1974,weekly!$H$2:$H$188,0)) -> 17309.704 | I1974: =INDEX(weekly!$F$2:$F$188,MATCH('Marketing Campaigns 22.11.22'!L1974,weekly!$H$2:$H$188,0)) -> 6353.2139 | J1974: 0 | K1974: 0 | L1974: =B1974&"-"&C1974&"-"&M1974 -> 27-7-2023 | M1974: =YEAR(A1974) -> 2023
A1975: =DATE(2023, 1, -2) - WEEKDAY(DATE(2023, 1, 3)) + B1975 * 7 -> 45110 | B1975: 27 | C1975: =MONTH(A1975) -> 7 | D1975: =CEILING(C1975 / 3,1) -> 3 | E1975: Backmischung | F1975: 0 | G1975: =INDEX(weekly!$E$2:$E$188,MATCH('Marketing Campaigns 22.11.22'!L1975,weekly!$H$2:$H$188,0)) -> 5937.136 | H1975: =INDEX(weekly!$D$2:$D$188,MATCH('Marketing Campaigns 22.11.22'!L1975,weekly!$H$2:$H$188,0)) -> 17309.704 | I1975: =INDEX(weekly!$F$2:$F$188,MATCH('Marketing Campaigns 22.11.22'!L1975,weekly!$H$2:$H$188,0)) -> 6353.2139 | J1975: 0 | K1975: 0 | L1975: =B1975&"-"&C1975&"-"&M1975 -> 27-7-2023 | M1975: =YEAR(A1975) -> 2023
A1976: =DATE(2023, 1, -2) - WEEKDAY(DATE(2023, 1, 3)) + B1976 * 7 -> 45110 | B1976: 27 | C1976: =MONTH(A1976) -> 7 | D1976: =CEILING(C1976 / 3,1) -> 3 | E1976: Nassfutter | F1976: 0 | G1976: =INDEX(weekly!$E$2:$E$188,MATCH('Marketing Campaigns 22.11.22'!L1976,weekly!$H$2:$H$188,0)) -> 5937.136 | H1976: =INDEX(weekly!$D$2:$D$188,MATCH('Marketing Campaigns 22.11.22'!L1976,weekly!$H$2:$H$188,0)) -> 17309.704 | I1976: =INDEX(weekly!$F$2:$F$188,MATCH('Marketing Campaigns 22.11.22'!L1976,weekly!$H$2:$H$188,0)) -> 6353.2139 | J1976: 0 | K1976: 0 | L1976: =B1976&"-"&C1976&"-"&M1976 -> 27-7-2023 | M1976: =YEAR(A1976) -> 2023
A1977: =DATE(2023, 1, -2) - WEEKDAY(DATE(2023, 1, 3)) + B1977 * 7 -> 45110 | B1977: 27 | C1977: =MONTH(A1977) -> 7 | D1977: =CEILING(C1977 / 3,1) -> 3 | E1977: Mixpaket | F1977: 0 | G1977: =INDEX(weekly!$E$2:$E$188,MATCH('Marketing Campaigns 22.11.22'!L1977,weekly!$H$2:$H$188,0)) -> 5937.136 | H1977: =INDEX(weekly!$D$2:$D$188,MATCH('Marketing Campaigns 22.11.22'!L1977,weekly!$H$2:$H$188,0)) -> 17309.704 | I1977: =INDEX(weekly!$F$2:$F$188,MATCH('Marketing Campaigns 22.11.22'!L1977,weekly!$H$2:$H$188,0)) -> 6353.2139 | J1977: 0 | K1977: 0 | L1977: =B1977&"-"&C1977&"-"&M1977 -> 27-7-2023 | M1977: =YEAR(A1977) -> 2023
A1978: =DATE(2023, 1, -2) - WEEKDAY(DATE(2023, 1, 3)) + B1978 * 7 -> 45110 | B1978: 27 | C1978: =MONTH(A1978) -> 7 | D1978: =CEILING(C1978 / 3,1) -> 3 | E1978: Premium Trockenfutter mit <br> Lamm, Süßkartoffel und Leinsamen <br> (400g / 2kg / 8kg / 12kg) | F1978: 0 | G1978: =INDEX(weekly!$E$2:$E$188,MATCH('Marketing Campaigns 22.11.22'!L1978,weekly!$H$2:$H$188,0)) -> 5937.136 | H1978: =INDEX(weekly!$D$2:$D$188,MATCH('Marketing Campaigns 22.11.22'!L1978,weekly!$H$2:$H$188,0)) -> 17309.704 | I1978: =INDEX(weekly!$F$2:$F$188,MATCH('Marketing Campaigns 22.11.22'!L1978,weekly!$H$2:$H$188,0)) -> 6353.2139 | J1978: 0 | K1978: 0 | L1978: =B1978&"-"&C1978&"-"&M1978 -> 27-7-2023 | M1978: =YEAR(A1978) -> 2023
A1979: =DATE(2023, 1, -2) - WEEKDAY(DATE(2023, 1, 3)) + B1979 * 7 -> 45110 | B1979: 27 | C1979: =MONTH(A1979) -> 7 | D1979: =CEILING(C1979 / 3,1) -> 3 | E1979: Trockenfutter | F1979: 0 | G1979: =INDEX(weekly!$E$2:$E$188,MATCH('Marketing Campaigns 22.11.22'!L1979,weekly!$H$2:$H$188,0)) -> 5937.136 | H1979: =INDEX(weekly!$D$2:$D$188,MATCH('Marketing Campaigns 22.11.22'!L1979,weekly!$H$2:$H$188,0)) -> 17309.704 | I1979: =INDEX(weekly!$F$2:$F$188,MATCH('Marketing Campaigns 22.11.22'!L1979,weekly!$H$2:$H$188,0)) -> 6353.2139 | J1979: 0 | K1979: 0 | L1979: =B1979&"-"&C1979&"-"&M1979 -> 27-7-2023 | M1979: =YEAR(A1979) -> 2023
... A1982: =DATE(2023, 1, -2) - WEEKDAY(DATE(2023, 1, 3)) + B1982 * 7 -> 45110 | B1982: 27 | C1982: =MONTH(A1982) -> 7 | D1982: =CEILING(C1982 / 3,1) -> 3 | E1982: DUMMY2 | F1982: 0 | G1982: =INDEX(weekly!$E$2:$E$188,MATCH('Marketing Campaigns 22.11.22'!L1982,weekly!$H$2:$H$188,0)) -> 5937.136 | H1982: =INDEX(weekly!$D$2:$D$188,MATCH('Marketing Campaigns 22.11.22'!L1982,weekly!$H$2:$H$188,0)) -> 17309.704 | I1982: =INDEX(weekly!$F$2:$F$188,MATCH('Marketing Campaigns 22.11.22'!L1982,weekly!$H$2:$H$188,0)) -> 6353.2139 | J1982: 0 | K1982: 0 | L1982: =B1982&"-"&C1982&"-"&M1982 -> 27-7-2023 | M1982: =YEAR(A1982) -> 2023
A1983: =DATE(2023, 1, -2) - WEEKDAY(DATE(2023, 1, 3)) + B1983 * 7 -> 45117 | B1983: =IF(E1983="None",B1982+1,B1982) -> 28 | C1983: =MONTH(A1983) -> 7 | D1983: =CEILING(C1983 / 3,1) -> 3 | E1983: None | F1983: 0 | G1983: =INDEX(weekly!$E$2:$E$188,MATCH('Marketing Campaigns 22.11.22'!L1983,weekly!$H$2:$H$188,0)) -> 5937.136 | H1983: =INDEX(weekly!$D$2:$D$188,MATCH('Marketing Campaigns 22.11.22'!L1983,weekly!$H$2:$H$188,0)) -> 17309.704 | I1983: =INDEX(weekly!$F$2:$F$188,MATCH('Marketing Campaigns 22.11.22'!L1983,weekly!$H$2:$H$188,0)) -> 6353.2139 | J1983: 0 | K1983: 0 | L1983: =B1983&"-"&C1983&"-"&M1983 -> 28-7-2023 | M1983: =YEAR(A1983) -> 2023
A1984: =DATE(2023, 1, -2) - WEEKDAY(DATE(2023, 1, 3)) + B1984 * 7 -> 45117 | B1984: =IF(E1984="None",B1983+1,B1983) -> 28 | C1984: =MONTH(A1984) -> 7 | D1984: =CEILING(C1984 / 3,1) -> 3 | E1984: Premium Truthahnhappen | F1984: 0 | G1984: =INDEX(weekly!$E$2:$E$188,MATCH('Marketing Campaigns 22.11.22'!L1984,weekly!$H$2:$H$188,0)) -> 5937.136 | H1984: =INDEX(weekly!$D$2:$D$188,MATCH('Marketing Campaigns 22.11.22'!L1984,weekly!$H$2:$H$188,0)) -> 17309.704 | I1984: =INDEX(weekly!$F$2:$F$188,MATCH('Marketing Campaigns 22.11.22'!L1984,weekly!$H$2:$H$188,0)) -> 6353.2139 | J1984: 0 | K1984: 0 | L1984: =B1984&"-"&C1984&"-"&M1984 -> 28-7-2023 | M1984: =YEAR(A1984) -> 2023
A1985: =DATE(2023, 1, -2) - WEEKDAY(DATE(2023, 1, 3)) + B1985 * 7 -> 45117 | B1985: =IF(E1985="None",B1984+1,B1984) -> 28 | C1985: =MONTH(A1985) -> 7 | D1985: =CEILING(C1985 / 3,1) -> 3 | E1985: Probierpaket | F1985: 0 | G1985: =INDEX(weekly!$E$2:$E$188,MATCH('Marketing Campaigns 22.11.22'!L1985,weekly!$H$2:$H$188,0)) -> 5937.136 | H1985: =INDEX(weekly!$D$2:$D$188,MATCH('Marketing Campaigns 22.11.22'!L1985,weekly!$H$2:$H$188,0)) -> 17309.704 | I1985: =INDEX(weekly!$F$2:$F$188,MATCH('Marketing Campaigns 22.11.22'!L1985,weekly!$H$2:$H$188,0)) -> 6353.2139 | J1985: 0 | K1985: 0 | L1985: =B1985&"-"&C1985&"-"&M1985 -> 28-7-2023 | M1985: =YEAR(A1985) -> 2023
A1986: =DATE(2023, 1, -2) - WEEKDAY(DATE(2023, 1, 3)) + B1986 * 7 -> 45117 | B1986: =IF(E1986="None",B1985+1,B1985) -> 28 | C1986: =MONTH(A1986) -> 7 | D1986: =CEILING(C1986 / 3,1) -> 3 | E1986: Premium Trockenfutter mit<br> Lachs und Süßkartoffel für sensible Katzenmägen <br> (1,5kg / 6kg) | F1986: 0 | G1986: =INDEX(weekly!$E$2:$E$188,MATCH('Marketing Campaigns 22.11.22'!L1986,weekly!$H$2:$H$188,0)) -> 5937.136 | H1986: =INDEX(weekly!$D$2:$D$188,MATCH('Marketing Campaigns 22.11.22'!L1986,weekly!$H$2:$H$188,0)) -> 17309.704 | I1986: =INDEX(weekly!$F$2:$F$188,MATCH('Marketing Campaigns 22.11.22'!L1986,weekly!$H$2:$H$188,0)) -> 6353.2139 | J1986: 0 | K1986: 0 | L1986: =B1986&"-"&C1986&"-"&M1986 -> 28-7-2023 | M1986: =YEAR(A1986) -> 2023
A1987: =DATE(2023, 1, -2) - WEEKDAY(DATE(2023, 1, 3)) + B1987 * 7 -> 45117 | B1987: =IF(E1987="None",B1986+1,B1986) -> 28 | C1987: =MONTH(A1987) -> 7 | D1987: =CEILING(C1987 / 3,1) -> 3 | E1987: Premium Trockenfutter mit <br> Lachs & Hering <br> (2kg / 12kg) | F1987: 0 | G1987: =INDEX(weekly!$E$2:$E$188,MATCH('Marketing Campaigns 22.11.22'!L1987,weekly!$H$2:$H$188,0)) -> 5937.136 | H1987: =INDEX(weekly!$D$2:$D$188,MATCH('Marketing Campaigns 22.11.22'!L1987,weekly!$H$2:$H$188,0)) -> 17309.704 | I1987: =INDEX(weekly!$F$2:$F$188,MATCH('Marketing Campaigns 22.11.22'!L1987,weekly!$H$2:$H$188,0)) -> 6353.2139 | J1987: 0 | K1987: 0 | L1987: =B1987&"-"&C1987&"-"&M1987 -> 28-7-2023 | M1987: =YEAR(A1987) -> 2023
A1988: =DATE(2023, 1, -2) - WEEKDAY(DATE(2023, 1, 3)) + B1988 * 7 -> 45117 | B1988: =IF(E1988="None",B1987+1,B1987) -> 28 | C1988: =MONTH(A1988) -> 7 | D1988: =CEILING(C1988 / 3,1) -> 3 | E1988: Funktionssnack | F1988: 0 | G1988: =INDEX(weekly!$E$2:$E$188,MATCH('Marketing Campaigns 22.11.22'!L1988,weekly!$H$2:$H$188,0)) -> 5937.136 | H1988: =INDEX(weekly!$D$2:$D$188,MATCH('Marketing Campaigns 22.11.22'!L1988,weekly!$H$2:$H$188,0)) -> 17309.704 | I1988: =INDEX(weekly!$F$2:$F$188,MATCH('Marketing Campaigns 22.11.22'!L1988,weekly!$H$2:$H$188,0)) -> 6353.2139 | J1988: 0 | K1988: 0 | L1988: =B1988&"-"&C1988&"-"&M1988 -> 28-7-2023 | M1988: =YEAR(A1988) -> 2023
A1989: =DATE(2023, 1, -2) - WEEKDAY(DATE(2023, 1, 3)) + B1989 * 7 -> 45117 | B1989: =IF(E1989="None",B1988+1,B1988) -> 28 | C1989: =MONTH(A1989) -> 7 | D1989: =CEILING(C1989 / 3,1) -> 3 | E1989: Snack | F1989: 0 | G1989: =INDEX(weekly!$E$2:$E$188,MATCH('Marketing Campaigns 22.11.22'!L1989,weekly!$H$2:$H$188,0)) -> 5937.136 | H1989: =INDEX(weekly!$D$2:$D$188,MATCH('Marketing Campaigns 22.11.22'!L1989,weekly!$H$2:$H$188,0)) -> 17309.704 | I1989: =INDEX(weekly!$F$2:$F$188,MATCH('Marketing Campaigns 22.11.22'!L1989,weekly!$H$2:$H$188,0)) -> 6353.2139 | J1989: 0 | K1989: 0 | L1989: =B1989&"-"&C1989&"-"&M1989 -> 28-7-2023 | M1989: =YEAR(A1989) -> 2023
A1990: =DATE(2023, 1, -2) - WEEKDAY(DATE(2023, 1, 3)) + B1990 * 7 -> 45117 | B1990: =IF(E1990="None",B1989+1,B1989) -> 28 | C1990: =MONTH(A1990) -> 7 | D1990: =CEILING(C1990 / 3,1) -> 3 | E1990: Backmischung | F1990: 0 | G1990: =INDEX(weekly!$E$2:$E$188,MATCH('Marketing Campaigns 22.11.22'!L1990,weekly!$H$2:$H$188,0)) -> 5937.136 | H1990: =INDEX(weekly!$D$2:$D$188,MATCH('Marketing Campaigns 22.11.22'!L1990,weekly!$H$2:$H$188,0)) -> 17309.704 | I1990: =INDEX(weekly!$F$2:$F$188,MATCH('Marketing Campaigns 22.11.22'!L1990,weekly!$H$2:$H$188,0)) -> 6353.2139 | J1990: 0 | K1990: 0 | L1990: =B1990&"-"&C1990&"-"&M1990 -> 28-7-2023 | M1990: =YEAR(A1990) -> 2023
A1991: =DATE(2023, 1, -2) - WEEKDAY(DATE(2023, 1, 3)) + B1991 * 7 -> 45117 | B1991: =IF(E1991="None",B1990+1,B1990) -> 28 | C1991: =MONTH(A1991) -> 7 | D1991: =CEILING(C1991 / 3,1) -> 3 | E1991: Nassfutter | F1991: 0 | G1991: =INDEX(weekly!$E$2:$E$188,MATCH('Marketing Campaigns 22.11.22'!L1991,weekly!$H$2:$H$188,0)) -> 5937.136 | H1991: =INDEX(weekly!$D$2:$D$188,MATCH('Marketing Campaigns 22.11.22'!L1991,weekly!$H$2:$H$188,0)) -> 17309.704 | I1991: =INDEX(weekly!$F$2:$F$188,MATCH('Marketing Campaigns 22.11.22'!L1991,weekly!$H$2:$H$188,0)) -> 6353.2139 | J1991: 0 | K1991: 0 | L1991: =B1991&"-"&C1991&"-"&M1991 -> 28-7-2023 | M1991: =YEAR(A1991) -> 2023
A1992: =DATE(2023, 1, -2) - WEEKDAY(DATE(2023, 1, 3)) + B1992 * 7 -> 45117 | B1992: =IF(E1992="None",B1991+1,B1991) -> 28 | C1992: =MONTH(A1992) -> 7 | D1992: =CEILING(C1992 / 3,1) -> 3 | E1992: Mixpaket | F1992: 0 | G1992: =INDEX(weekly!$E$2:$E$188,MATCH('Marketing Campaigns 22.11.22'!L1992,weekly!$H$2:$H$188,0)) -> 5937.136 | H1992: =INDEX(weekly!$D$2:$D$188,MATCH('Marketing Campaigns 22.11.22'!L1992,weekly!$H$2:$H$188,0)) -> 17309.704 | I1992: =INDEX(weekly!$F$2:$F$188,MATCH('Marketing Campaigns 22.11.22'!L1992,weekly!$H$2:$H$188,0)) -> 6353.2139 | J1992: 0 | K1992: 0 | L1992: =B1992&"-"&C1992&"-"&M1992 -> 28-7-2023 | M1992: =YEAR(A1992) -> 2023
A1993: =DATE(2023, 1, -2) - WEEKDAY(DATE(2023, 1, 3)) + B1993 * 7 -> 45117 | B1993: =IF(E1993="None",B1992+1,B1992) -> 28 | C1993: =MONTH(A1993) -> 7 | D1993: =CEILING(C1993 / 3,1) -> 3 | E1993: Premium Trockenfutter mit <br> Lamm, Süßkartoffel und Leinsamen <br> (400g / 2kg / 8kg / 12kg) | F1993: 0 | G1993: =INDEX(weekly!$E$2:$E$188,MATCH('Marketing Campaigns 22.11.22'!L1993,weekly!$H$2:$H$188,0)) -> 5937.136 | H1993: =INDEX(weekly!$D$2:$D$188,MATCH('Marketing Campaigns 22.11.22'!L1993,weekly!$H$2:$H$188,0)) -> 17309.704 | I1993: =INDEX(weekly!$F$2:$F$188,MATCH('Marketing Campaigns 22.11.22'!L1993,weekly!$H$2:$H$188,0)) -> 6353.2139 | J1993: 0 | K1993: 0 | L1993: =B1993&"-"&C1993&"-"&M1993 -> 28-7-2023 | M1993: =YEAR(A1993) -> 2023
A1994: =DATE(2023, 1, -2) - WEEKDAY(DATE(2023, 1, 3)) + B1994 * 7 -> 45117 | B1994: =IF(E1994="None",B1993+1,B1993) -> 28 | C1994: =MONTH(A1994) -> 7 | D1994: =CEILING(C1994 / 3,1) -> 3 | E1994: Trockenfutter | F1994: 0 | G1994: =INDEX(weekly!$E$2:$E$188,MATCH('Marketing Campaigns 22.11.22'!L1994,weekly!$H$2:$H$188,0)) -> 5937.136 | H1994: =INDEX(weekly!$D$2:$D$188,MATCH('Marketing Campaigns 22.11.22'!L1994,weekly!$H$2:$H$188,0)) -> 17309.704 | I1994: =INDEX(weekly!$F$2:$F$188,MATCH('Marketing Campaigns 22.11.22'!L1994,weekly!$H$2:$H$188,0)) -> 6353.2139 | J1994: 0 | K1994: 0 | L1994: =B1994&"-"&C1994&"-"&M1994 -> 28-7-2023 | M1994: =YEAR(A1994) -> 2023
...

Sheet planning dogs-n-tiger
A1: date | B1: spend_google | C1: spend_facebook | D1: spend_rest | E1: month | F1: year | G1: month_year
A2: 44409 | B2: 1813 | C2: 4720.17 | D2: 0 | E2: =MONTH(A2) -> 8 | F2: =YEAR(A2) -> 2021 | G2: =E2&F2 -> 82021
A3: 44440 | B3: 5089 | C3: 7134 | D3: 0 | E3: =MONTH(A3) -> 9 | F3: =YEAR(A3) -> 2021 | G3: =E3&F3 -> 92021
A4: 44470 | B4: 3547 | C4: 19008.99 | D4: 0 | E4: =MONTH(A4) -> 10 | F4: =YEAR(A4) -> 2021 | G4: =E4&F4 -> 102021
A5: 44501 | B5: 2687 | C5: 25508 | D5: 0 | E5: =MONTH(A5) -> 11 | F5: =YEAR(A5) -> 2021 | G5: =E5&F5 -> 112021
A6: 44531 | B6: 2998 | C6: 14357.28 | D6: 0 | E6: =MONTH(A6) -> 12 | F6: =YEAR(A6) -> 2021 | G6: =E6&F6 -> 122021
A7: 44562 | B7: 3515 | C7: 22889.31 | D7: 0 | E7: =MONTH(A7) -> 1 | F7: =YEAR(A7) -> 2022 | G7: =E7&F7 -> 12022
A8: 44593 | B8: 10879 | C8: 25600.37 | D8: 0 | E8: =MONTH(A8) -> 2 | F8: =YEAR(A8) -> 2022 | G8: =E8&F8 -> 22022
A9: 44621 | B9: 19084 | C9: 25764.03 | D9: 0 | E9: =MONTH(A9) -> 3 | F9: =YEAR(A9) -> 2022 | G9: =E9&F9 -> 32022
A10: 44652 | B10: 25388 | C10: 25521 | D10: 4129 | E10: =MONTH(A10) -> 4 | F10: =YEAR(A10) -> 2022 | G10: =E10&F10 -> 42022
A11: 44682 | B11: 36425 | C11: 29226 | D11: 19536 | E11: =MONTH(A11) -> 5 | F11: =YEAR(A11) -> 2022 | G11: =E11&F11 -> 52022
A12: 44713 | B12: 40310 | C12: 20652.35 | D12: 22461.92 | E12: =MONTH(A12) -> 6 | F12: =YEAR(A12) -> 2022 | G12: =E12&F12 -> 62022
A13: 44743 | B13: 46895 | C13: 24102.24 | D13: 17717.89 | E13: =MONTH(A13) -> 7 | F13: =YEAR(A13) -> 2022 | G13: =E13&F13 -> 72022
... A23: 45047 | B23: 60000 | C23: 30000 | D23: 15000 | E23: =MONTH(A23) -> 5 | F23: =YEAR(A23) -> 2023 | G23: =E23&F23 -> 52023
A24: 45078 | B24: =_xlfn.FORECAST.ETS($A24,B$2:B$23,$A$2:$A$23,12,1,1) -> 71073.369 | C24: =_xlfn.FORECAST.ETS($A24,C$2:C$23,$A$2:$A$23,12,1,1) -> 23158.443 | D24: =_xlfn.FORECAST.ETS($A24,D$2:D$23,$A$2:$A$23,12,1,1) -> 32959.837 | E24: =MONTH(A24) -> 6 | F24: =YEAR(A24) -> 2023 | G24: =E24&F24 -> 62023
A25: 45108 | B25: =_xlfn.FORECAST.ETS($A25,B$2:B$23,$A$2:$A$23,12,1,1) -> 76657.259 | C25: =_xlfn.FORECAST.ETS($A25,C$2:C$23,$A$2:$A$23,12,1,1) -> 26293.031 | D25: =_xlfn.FORECAST.ETS($A25,D$2:D$23,$A$2:$A$23,12,1,1) -> 28135.662 | E25: =MONTH(A25) -> 7 | F25: =YEAR(A25) -> 2023 | G25: =E25&F25 -> 72023
A26: 45139 | B26: =_xlfn.FORECAST.ETS($A26,B$2:B$23,$A$2:$A$23,12,1,1) -> 76991.885 | C26: =_xlfn.FORECAST.ETS($A26,C$2:C$23,$A$2:$A$23,12,1,1) -> 24300.329 | D26: =_xlfn.FORECAST.ETS($A26,D$2:D$23,$A$2:$A$23,12,1,1) -> 26570.54 | E26: =MONTH(A26) -> 8 | F26: =YEAR(A26) -> 2023 | G26: =E26&F26 -> 82023
A27: 45170 | B27: =_xlfn.FORECAST.ETS($A27,B$2:B$23,$A$2:$A$23,12,1,1) -> 71272.577 | C27: =_xlfn.FORECAST.ETS($A27,C$2:C$23,$A$2:$A$23,12,1,1) -> 28486.721 | D27: =_xlfn.FORECAST.ETS($A27,D$2:D$23,$A$2:$A$23,12,1,1) -> 26073.819 | E27: =MONTH(A27) -> 9 | F27: =YEAR(A27) -> 2023 | G27: =E27&F27 -> 92023
A28: 45200 | B28: =_xlfn.FORECAST.ETS($A28,B$2:B$23,$A$2:$A$23,12,1,1) -> 75878.621 | C28: =_xlfn.FORECAST.ETS($A28,C$2:C$23,$A$2:$A$23,12,1,1) -> 34489.476 | D28: =_xlfn.FORECAST.ETS($A28,D$2:D$23,$A$2:$A$23,12,1,1) -> 17790.75 | E28: =MONTH(A28) -> 10 | F28: =YEAR(A28) -> 2023 | G28: =E28&F28 -> 102023
A29: 45231 | B29: =_xlfn.FORECAST.ETS($A29,B$2:B$23,$A$2:$A$23,12,1,1) -> 71229.952 | C29: =_xlfn.FORECAST.ETS($A29,C$2:C$23,$A$2:$A$23,12,1,1) -> 25187.208 | D29: =_xlfn.FORECAST.ETS($A29,D$2:D$23,$A$2:$A$23,12,1,1) -> 20033.094 | E29: =MONTH(A29) -> 11 | F29: =YEAR(A29) -> 2023 | G29: =E29&F29 -> 112023
A30: 45261 | B30: =_xlfn.FORECAST.ETS($A30,B$2:B$23,$A$2:$A$23,12,1,1) -> 75432.269 | C30: =_xlfn.FORECAST.ETS($A30,C$2:C$23,$A$2:$A$23,12,1,1) -> 21775.292 | D30: =_xlfn.FORECAST.ETS($A30,D$2:D$23,$A$2:$A$23,12,1,1) -> 20610.204 | E30: =MONTH(A30) -> 12 | F30: =YEAR(A30) -> 2023 | G30: =E30&F30 -> 122023

Sheet transformed
A1: day | B1: spend_google | C1: spend_facebook | D1: rest_spend | E1: iso_week | F1: month | G1: year | H1: month_year | I1: days per month | J1: spend_google | K1: spend_facebook | L1: rest_spend | M1: week_year | N1: week_year_month
A2: 44197 | B2: =IFERROR(INDEX('planning dogs-n-tiger'!B$1:B$30,MATCH($H2,'planning dogs-n-tiger'!$G$1:$G$42,0)),0) -> 0 | C2: =IFERROR(INDEX('planning dogs-n-tiger'!C$1:C$30,MATCH($H2,'planning dogs-n-tiger'!$G$1:$G$42,0)),0) -> 0 | D2: =IFERROR(INDEX('planning dogs-n-tiger'!D$1:D$30,MATCH($H2,'planning dogs-n-tiger'!$G$1:$G$42,0)),0) -> 0 | E2: =_xlfn.ISOWEEKNUM(A2) -> 53 | F2: =MONTH(A2) -> 1 | G2: =YEAR(A2) -> 2021 | H2: =F2&G2 -> 12021 | I2: =DAY(EOMONTH(DATE(G2,F2,0),1)) -> 31 | J2: =B2/$I2 -> 0 | K2: =C2/$I2 -> 0 | L2: =D2/$I2 -> 0 | M2: =E2&G2 -> 532021 | N2: =E2&"-"&F2&"-"&G2 -> 53-1-2021
A3: 44198 | B3: =IFERROR(INDEX('planning dogs-n-tiger'!B$1:B$30,MATCH($H3,'planning dogs-n-tiger'!$G$1:$G$42,0)),0) -> 0 | C3: =IFERROR(INDEX('planning dogs-n-tiger'!C$1:C$30,MATCH($H3,'planning dogs-n-tiger'!$G$1:$G$42,0)),0) -> 0 | D3: =IFERROR(INDEX('planning dogs-n-tiger'!D$1:D$30,MATCH($H3,'planning dogs-n-tiger'!$G$1:$G$42,0)),0) -> 0 | E3: =_xlfn.ISOWEEKNUM(A3) -> 53 | F3: =MONTH(A3) -> 1 | G3: =YEAR(A3) -> 2021 | H3: =F3&G3 -> 12021 | I3: =DAY(EOMONTH(DATE(G3,F3,0),1)) -> 31 | J3: =B3/$I3 -> 0 | K3: =C3/$I3 -> 0 | L3: =D3/$I3 -> 0 | M3: =E3&G3 -> 532021 | N3: =E3&"-"&F3&"-"&G3 -> 53-1-2021
A4: 44199 | B4: =IFERROR(INDEX('planning dogs-n-tiger'!B$1:B$30,MATCH($H4,'planning dogs-n-tiger'!$G$1:$G$42,0)),0) -> 0 | C4: =IFERROR(INDEX('planning dogs-n-tiger'!C$1:C$30,MATCH($H4,'planning dogs-n-tiger'!$G$1:$G$42,0)),0) -> 0 | D4: =IFERROR(INDEX('planning dogs-n-tiger'!D$1:D$30,MATCH($H4,'planning dogs-n-tiger'!$G$1:$G$42,0)),0) -> 0 | E4: =_xlfn.ISOWEEKNUM(A4) -> 53 | F4: =MONTH(A4) -> 1 | G4: =YEAR(A4) -> 2021 | H4: =F4&G4 -> 12021 | I4: =DAY(EOMONTH(DATE(G4,F4,0),1)) -> 31 | J4: =B4/$I4 -> 0 | K4: =C4/$I4 -> 0 | L4: =D4/$I4 -> 0 | M4: =E4&G4 -> 532021 | N4: =E4&"-"&F4&"-"&G4 -> 53-1-2021
A5: 44200 | B5: =IFERROR(INDEX('planning dogs-n-tiger'!B$1:B$30,MATCH($H5,'planning dogs-n-tiger'!$G$1:$G$42,0)),0) -> 0 | C5: =IFERROR(INDEX('planning dogs-n-tiger'!C$1:C$30,MATCH($H5,'planning dogs-n-tiger'!$G$1:$G$42,0)),0) -> 0 | D5: =IFERROR(INDEX('planning dogs-n-tiger'!D$1:D$30,MATCH($H5,'planning dogs-n-tiger'!$G$1:$G$42,0)),0) -> 0 | E5: =_xlfn.ISOWEEKNUM(A5) -> 1 | F5: =MONTH(A5) -> 1 | G5: =YEAR(A5) -> 2021 | H5: =F5&G5 -> 12021 | I5: =DAY(EOMONTH(DATE(G5,F5,0),1)) -> 31 | J5: =B5/$I5 -> 0 | K5: =C5/$I5 -> 0 | L5: =D5/$I5 -> 0 | M5: =E5&G5 -> 12021 | N5: =E5&"-"&F5&"-"&G5 -> 1-1-2021
A6: 44201 | B6: =IFERROR(INDEX('planning dogs-n-tiger'!B$1:B$30,MATCH($H6,'planning dogs-n-tiger'!$G$1:$G$42,0)),0) -> 0 | C6: =IFERROR(INDEX('planning dogs-n-tiger'!C$1:C$30,MATCH($H6,'planning dogs-n-tiger'!$G$1:$G$42,0)),0) -> 0 | D6: =IFERROR(INDEX('planning dogs-n-tiger'!D$1:D$30,MATCH($H6,'planning dogs-n-tiger'!$G$1:$G$42,0)),0) -> 0 | E6: =_xlfn.ISOWEEKNUM(A6) -> 1 | F6: =MONTH(A6) -> 1 | G6: =YEAR(A6) -> 2021 | H6: =F6&G6 -> 12021 | I6: =DAY(EOMONTH(DATE(G6,F6,0),1)) -> 31 | J6: =B6/$I6 -> 0 | K6: =C6/$I6 -> 0 | L6: =D6/$I6 -> 0 | M6: =E6&G6 -> 12021 | N6: =E6&"-"&F6&"-"&G6 -> 1-1-2021
A7: 44202 | B7: =IFERROR(INDEX('planning dogs-n-tiger'!B$1:B$30,MATCH($H7,'planning dogs-n-tiger'!$G$1:$G$42,0)),0) -> 0 | C7: =IFERROR(INDEX('planning dogs-n-tiger'!C$1:C$30,MATCH($H7,'planning dogs-n-tiger'!$G$1:$G$42,0)),0) -> 0 | D7: =IFERROR(INDEX('planning dogs-n-tiger'!D$1:D$30,MATCH($H7,'planning dogs-n-tiger'!$G$1:$G$42,0)),0) -> 0 | E7: =_xlfn.ISOWEEKNUM(A7) -> 1 | F7: =MONTH(A7) -> 1 | G7: =YEAR(A7) -> 2021 | H7: =F7&G7 -> 12021 | I7: =DAY(EOMONTH(DATE(G7,F7,0),1)) -> 31 | J7: =B7/$I7 -> 0 | K7: =C7/$I7 -> 0 | L7: =D7/$I7 -> 0 | M7: =E7&G7 -> 12021 | N7: =E7&"-"&F7&"-"&G7 -> 1-1-2021
A8: 44203 | B8: =IFERROR(INDEX('planning dogs-n-tiger'!B$1:B$30,MATCH($H8,'planning dogs-n-tiger'!$G$1:$G$42,0)),0) -> 0 | C8: =IFERROR(INDEX('planning dogs-n-tiger'!C$1:C$30,MATCH($H8,'planning dogs-n-tiger'!$G$1:$G$42,0)),0) -> 0 | D8: =IFERROR(INDEX('planning dogs-n-tiger'!D$1:D$30,MATCH($H8,'planning dogs-n-tiger'!$G$1:$G$42,0)),0) -> 0 | E8: =_xlfn.ISOWEEKNUM(A8) -> 1 | F8: =MONTH(A8) -> 1 | G8: =YEAR(A8) -> 2021 | H8: =F8&G8 -> 12021 | I8: =DAY(EOMONTH(DATE(G8,F8,0),1)) -> 31 | J8: =B8/$I8 -> 0 | K8: =C8/$I8 -> 0 | L8: =D8/$I8 -> 0 | M8: =E8&G8 -> 12021 | N8: =E8&"-"&F8&"-"&G8 -> 1-1-2021
A9: 44204 | B9: =IFERROR(INDEX('planning dogs-n-tiger'!B$1:B$30,MATCH($H9,'planning dogs-n-tiger'!$G$1:$G$42,0)),0) -> 0 | C9: =IFERROR(INDEX('planning dogs-n-tiger'!C$1:C$30,MATCH($H9,'planning dogs-n-tiger'!$G$1:$G$42,0)),0) -> 0 | D9: =IFERROR(INDEX('planning dogs-n-tiger'!D$1:D$30,MATCH($H9,'planning dogs-n-tiger'!$G$1:$G$42,0)),0) -> 0 | E9: =_xlfn.ISOWEEKNUM(A9) -> 1 | F9: =MONTH(A9) -> 1 | G9: =YEAR(A9) -> 2021 | H9: =F9&G9 -> 12021 | I9: =DAY(EOMONTH(DATE(G9,F9,0),1)) -> 31 | J9: =B9/$I9 -> 0 | K9: =C9/$I9 -> 0 | L9: =D9/$I9 -> 0 | M9: =E9&G9 -> 12021 | N9: =E9&"-"&F9&"-"&G9 -> 1-1-2021
A10: 44205 | B10: =IFERROR(INDEX('planning dogs-n-tiger'!B$1:B$30,MATCH($H10,'planning dogs-n-tiger'!$G$1:$G$42,0)),0) -> 0 | C10: =IFERROR(INDEX('planning dogs-n-tiger'!C$1:C$30,MATCH($H10,'planning dogs-n-tiger'!$G$1:$G$42,0)),0) -> 0 | D10: =IFERROR(INDEX('planning dogs-n-tiger'!D$1:D$30,MATCH($H10,'planning dogs-n-tiger'!$G$1:$G$42,0)),0) -> 0 | E10: =_xlfn.ISOWEEKNUM(A10) -> 1 | F10: =MONTH(A10) -> 1 | G10: =YEAR(A10) -> 2021 | H10: =F10&G10 -> 12021 | I10: =DAY(EOMONTH(DATE(G10,F10,0),1)) -> 31 | J10: =B10/$I10 -> 0 | K10: =C10/$I10 -> 0 | L10: =D10/$I10 -> 0 | M10: =E10&G10 -> 12021 | N10: =E10&"-"&F10&"-"&G10 -> 1-1-2021
A11: 44206 | B11: =IFERROR(INDEX('planning dogs-n-tiger'!B$1:B$30,MATCH($H11,'planning dogs-n-tiger'!$G$1:$G$42,0)),0) -> 0 | C11: =IFERROR(INDEX('planning dogs-n-tiger'!C$1:C$30,MATCH($H11,'planning dogs-n-tiger'!$G$1:$G$42,0)),0) -> 0 | D11: =IFERROR(INDEX('planning dogs-n-tiger'!D$1:D$30,MATCH($H11,'planning dogs-n-tiger'!$G$1:$G$42,0)),0) -> 0 | E11: =_xlfn.ISOWEEKNUM(A11) -> 1 | F11: =MONTH(A11) -> 1 | G11: =YEAR(A11) -> 2021 | H11: =F11&G11 -> 12021 | I11: =DAY(EOMONTH(DATE(G11,F11,0),1)) -> 31 | J11: =B11/$I11 -> 0 | K11: =C11/$I11 -> 0 | L11: =D11/$I11 -> 0 | M11: =E11&G11 -> 12021 | N11: =E11&"-"&F11&"-"&G11 -> 1-1-2021
A12: 44207 | B12: =IFERROR(INDEX('planning dogs-n-tiger'!B$1:B$30,MATCH($H12,'planning dogs-n-tiger'!$G$1:$G$42,0)),0) -> 0 | C12: =IFERROR(INDEX('planning dogs-n-tiger'!C$1:C$30,MATCH($H12,'planning dogs-n-tiger'!$G$1:$G$42,0)),0) -> 0 | D12: =IFERROR(INDEX('planning dogs-n-tiger'!D$1:D$30,MATCH($H12,'planning dogs-n-tiger'!$G$1:$G$42,0)),0) -> 0 | E12: =_xlfn.ISOWEEKNUM(A12) -> 2 | F12: =MONTH(A12) -> 1 | G12: =YEAR(A12) -> 2021 | H12: =F12&G12 -> 12021 | I12: =DAY(EOMONTH(DATE(G12,F12,0),1)) -> 31 | J12: =B12/$I12 -> 0 | K12: =C12/$I12 -> 0 | L12: =D12/$I12 -> 0 | M12: =E12&G12 -> 22021 | N12: =E12&"-"&F12&"-"&G12 -> 2-1-2021
A13: 44208 | B13: =IFERROR(INDEX('planning dogs-n-tiger'!B$1:B$30,MATCH($H13,'planning dogs-n-tiger'!$G$1:$G$42,0)),0) -> 0 | C13: =IFERROR(INDEX('planning dogs-n-tiger'!C$1:C$30,MATCH($H13,'planning dogs-n-tiger'!$G$1:$G$42,0)),0) -> 0 | D13: =IFERROR(INDEX('planning dogs-n-tiger'!D$1:D$30,MATCH($H13,'planning dogs-n-tiger'!$G$1:$G$42,0)),0) -> 0 | E13: =_xlfn.ISOWEEKNUM(A13) -> 2 | F13: =MONTH(A13) -> 1 | G13: =YEAR(A13) -> 2021 | H13: =F13&G13 -> 12021 | I13: =DAY(EOMONTH(DATE(G13,F13,0),1)) -> 31 | J13: =B13/$I13 -> 0 | K13: =C13/$I13 -> 0 | L13: =D13/$I13 -> 0 | M13: =E13&G13 -> 22021 | N13: =E13&"-"&F13&"-"&G13 -> 2-1-2021
... A1096: 45291 | B1096: =IFERROR(INDEX('planning dogs-n-tiger'!B$1:B$30,MATCH($H1096,'planning dogs-n-tiger'!$G$1:$G$42,0)),0) -> 75432.269 | C1096: =IFERROR(INDEX('planning dogs-n-tiger'!C$1:C$30,MATCH($H1096,'planning dogs-n-tiger'!$G$1:$G$42,0)),0) -> 21775.292 | D1096: =IFERROR(INDEX('planning dogs-n-tiger'!D$1:D$30,MATCH($H1096,'planning dogs-n-tiger'!$G$1:$G$42,0)),0) -> 20610.204 | E1096: =_xlfn.ISOWEEKNUM(A1096) -> 52 | F1096: =MONTH(A1096) -> 12 | G1096: =YEAR(A1096) -> 2023 | H1096: =F1096&G1096 -> 122023 | I1096: =DAY(EOMONTH(DATE(G1096,F1096,0),1)) -> 31 | J1096: =B1096/$I1096 -> 2433.299 | K1096: =C1096/$I1096 -> 702.42877 | L1096: =D1096/$I1096 -> 664.8453 | M1096: =E1096&G1096 -> 522023 | N1096: =E1096&"-"&F1096&"-"&G1096 -> 52-12-2023

Sheet weekly
A1: iso_week | B1: month | C1: year | D1: spend_google | E1: spend_facebook | F1: spend_rest | G1: week_year | H1: week_year_month
A2: 53 | B2: 1 | C2: 2021 | D2: =SUMIF(transformed!$N:$N,weekly!$H2,transformed!J:J) -> 0 | E2: =SUMIF(transformed!$N:$N,weekly!$H2,transformed!K:K) -> 0 | F2: =SUMIF(transformed!$N:$N,weekly!$H2,transformed!L:L) -> 0 | G2: =A2&C2 -> 532021 | H2: =A2&"-"&B2&"-"&C2 -> 53-1-2021
A3: 1 | B3: 1 | C3: 2021 | D3: =SUMIF(transformed!$N:$N,weekly!$H3,transformed!J:J) -> 0 | E3: =SUMIF(transformed!$N:$N,weekly!$H3,transformed!K:K) -> 0 | F3: =SUMIF(transformed!$N:$N,weekly!$H3,transformed!L:L) -> 0 | G3: =A3&C3 -> 12021 | H3: =A3&"-"&B3&"-"&C3 -> 1-1-2021
A4: 2 | B4: 1 | C4: 2021 | D4: =SUMIF(transformed!$N:$N,weekly!$H4,transformed!J:J) -> 0 | E4: =SUMIF(transformed!$N:$N,weekly!$H4,transformed!K:K) -> 0 | F4: =SUMIF(transformed!$N:$N,weekly!$H4,transformed!L:L) -> 0 | G4: =A4&C4 -> 22021 | H4: =A4&"-"&B4&"-"&C4 -> 2-1-2021
A5: 3 | B5: 1 | C5: 2021 | D5: =SUMIF(transformed!$N:$N,weekly!$H5,transformed!J:J) -> 0 | E5: =SUMIF(transformed!$N:$N,weekly!$H5,transformed!K:K) -> 0 | F5: =SUMIF(transformed!$N:$N,weekly!$H5,transformed!L:L) -> 0 | G5: =A5&C5 -> 32021 | H5: =A5&"-"&B5&"-"&C5 -> 3-1-2021
A6: 4 | B6: 1 | C6: 2021 | D6: =SUMIF(transformed!$N:$N,weekly!$H6,transformed!J:J) -> 0 | E6: =SUMIF(transformed!$N:$N,weekly!$H6,transformed!K:K) -> 0 | F6: =SUMIF(transformed!$N:$N,weekly!$H6,transformed!L:L) -> 0 | G6: =A6&C6 -> 42021 | H6: =A6&"-"&B6&"-"&C6 -> 4-1-2021
A7: 5 | B7: 2 | C7: 2021 | D7: =SUMIF(transformed!$N:$N,weekly!$H7,transformed!J:J) -> 0 | E7: =SUMIF(transformed!$N:$N,weekly!$H7,transformed!K:K) -> 0 | F7: =SUMIF(transformed!$N:$N,weekly!$H7,transformed!L:L) -> 0 | G7: =A7&C7 -> 52021 | H7: =A7&"-"&B7&"-"&C7 -> 5-2-2021
A8: 6 | B8: 2 | C8: 2021 | D8: =SUMIF(transformed!$N:$N,weekly!$H8,transformed!J:J) -> 0 | E8: =SUMIF(transformed!$N:$N,weekly!$H8,transformed!K:K) -> 0 | F8: =SUMIF(transformed!$N:$N,weekly!$H8,transformed!L:L) -> 0 | G8: =A8&C8 -> 62021 | H8: =A8&"-"&B8&"-"&C8 -> 6-2-2021
A9: 7 | B9: 2 | C9: 2021 | D9: =SUMIF(transformed!$N:$N,weekly!$H9,transformed!J:J) -> 0 | E9: =SUMIF(transformed!$N:$N,weekly!$H9,transformed!K:K) -> 0 | F9: =SUMIF(transformed!$N:$N,weekly!$H9,transformed!L:L) -> 0 | G9: =A9&C9 -> 72021 | H9: =A9&"-"&B9&"-"&C9 -> 7-2-2021
A10: 8 | B10: 2 | C10: 2021 | D10: =SUMIF(transformed!$N:$N,weekly!$H10,transformed!J:J) -> 0 | E10: =SUMIF(transformed!$N:$N,weekly!$H10,transformed!K:K) -> 0 | F10: =SUMIF(transformed!$N:$N,weekly!$H10,transformed!L:L) -> 0 | G10: =A10&C10 -> 82021 | H10: =A10&"-"&B10&"-"&C10 -> 8-2-2021
A11: 9 | B11: 3 | C11: 2021 | D11: =SUMIF(transformed!$N:$N,weekly!$H11,transformed!J:J) -> 0 | E11: =SUMIF(transformed!$N:$N,weekly!$H11,transformed!K:K) -> 0 | F11: =SUMIF(transformed!$N:$N,weekly!$H11,transformed!L:L) -> 0 | G11: =A11&C11 -> 92021 | H11: =A11&"-"&B11&"-"&C11 -> 9-3-2021
A12: 10 | B12: 3 | C12: 2021 | D12: =SUMIF(transformed!$N:$N,weekly!$H12,transformed!J:J) -> 0 | E12: =SUMIF(transformed!$N:$N,weekly!$H12,transformed!K:K) -> 0 | F12: =SUMIF(transformed!$N:$N,weekly!$H12,transformed!L:L) -> 0 | G12: =A12&C12 -> 102021 | H12: =A12&"-"&B12&"-"&C12 -> 10-3-2021
A13: 11 | B13: 3 | C13: 2021 | D13: =SUMIF(transformed!$N:$N,weekly!$H13,transformed!J:J) -> 0 | E13: =SUMIF(transformed!$N:$N,weekly!$H13,transformed!K:K) -> 0 | F13: =SUMIF(transformed!$N:$N,weekly!$H13,transformed!L:L) -> 0 | G13: =A13&C13 -> 112021 | H13: =A13&"-"&B13&"-"&C13 -> 11-3-2021
... A188: 52 | B188: 12 | C188: 2023 | D188: =SUMIF(transformed!$N:$N,weekly!$H188,transformed!J:J) -> 17033.093 | E188: =SUMIF(transformed!$N:$N,weekly!$H188,transformed!K:K) -> 4917.0014 | F188: =SUMIF(transformed!$N:$N,weekly!$H188,transformed!L:L) -> 4653.9171 | G188: =A188&C188 -> 522023 | H188: =A188&"-"&B188&"-"&C188 -> 52-12-2023

Sheet Sheet1
A1: categories
A2: Premium Truthahnhappen
A3: None
A4: Probierpaket
A5: Premium Trockenfutter mit<br> Lachs und Süßkartoffel für sensible Katzenmägen <br> (1,5kg / 6kg)
A6: Premium Trockenfutter mit <br> Lachs & Hering <br> (2kg / 12kg)
A7: Funktionssnack
A8: Snack
A9: Backmischung
A10: Nassfutter
A11: Mixpaket
A12: Premium Trockenfutter mit <br> Lamm, Süßkartoffel und Leinsamen <br> (400g / 2kg / 8kg / 12kg)
... A14: Junior Premium Trockenfutter<br> mit Huhn, Süßkartoffel und Krill <br> (400g / 1,5kg / 6kg)

Sheet Pricing
A1: Keys & Granularity | H1: Features
A2: Day | B2: Week | C2: Month | D2: Quarter | E2: Sku | F2: Category | G2: All | H2: sku_price_brutto_planned | I2: sku_promotion_planned | J2: sku_promotion_discount_planned | K2: sku_promotion_discount_communicated_planned
A3: 44562 | B3: 1 | C3: 1 | D3: 1 | E3: 1 | F3: 1 | G3: 1 | H3: 20 | I3: 1 | J3: 0.2 | K3: 1
A4: 44562 | B4: 1 | C4: 1 | D4: 1 | E4: 2 | F4: 2 | G4: 1 | H4: 25 | I4: 0 | J4: 0.3 | K4: 0
